Workbook

Sheet Смета
A1: ЛОКАЛЬНАЯ СМЕТА на ремонт квартиры «под ключ» — шаблон с примером
A2: Объект: ПРИМЕР, квартира 55 м², Минск. Профиль: штукатурка только новых перегородок, шпаклёвка Q3 по существующим стенам, самонивелир 5 мм + клеевой кварцвинил. Цены: розница Минска и ставки «типично», срез 27.09.2026, BYN без НДС.
A3: Как пользоваться: объёмы (жёлтые ячейки) — с листа «Объёмы» или вручную; цены тянутся по коду узла с листа «Узлы» (материал) и «Ставки» (работа). Класс отделки, объёмы и цены согласовать с заказчиком письменно до старта (ст. 663 ГК, ст. 34 ЗПП).
A5: № | B5: Код узла | C5: Наименование работ и затрат | D5: Ед. | E5: Объём | F5: Работа, BYN/ед. | G5: Материал, BYN/ед. | H5: Работа, BYN | I5: Материал, BYN | J5: Всего, BYN | K5: Обоснование / примечание
C6: 1. Подготовка и демонтаж
A7: 1 | B7: N01 | C7: =INDEX(Узлы!$B$2:$B$28,MATCH(B7,Узлы!$A$2:$A$28,0)) -> Демонтаж обоев | D7: =INDEX(Узлы!$C$2:$C$28,MATCH(B7,Узлы!$A$2:$A$28,0)) -> м² | E7: =Объёмы!$I$9 -> 131.99 | F7: =INDEX(Узлы!$G$2:$G$28,MATCH(B7,Узлы!$A$2:$A$28,0)) -> 3 | G7: =INDEX(Узлы!$E$2:$E$28,MATCH(B7,Узлы!$A$2:$A$28,0)) -> 0 | H7: =E7*F7 -> 395.97 | I7: =E7*G7 -> 0 | J7: =H7+I7 -> 395.97 | K7: снятие старых обоев со всех существующих стен
A8: 2 | B8: N02 | C8: =INDEX(Узлы!$B$2:$B$28,MATCH(B8,Узлы!$A$2:$A$28,0)) -> Демонтаж плинтуса | D8: =INDEX(Узлы!$C$2:$C$28,MATCH(B8,Узлы!$A$2:$A$28,0)) -> м.п. | E8: =Объёмы!$L$9 -> 39.8 | F8: =INDEX(Узлы!$G$2:$G$28,MATCH(B8,Узлы!$A$2:$A$28,0)) -> 3 | G8: =INDEX(Узлы!$E$2:$E$28,MATCH(B8,Узлы!$A$2:$A$28,0)) -> 0 | H8: =E8*F8 -> 119.4 | I8: =E8*G8 -> 0 | J8: =H8+I8 -> 119.4
A9: 3 | B9: N03 | C9: =INDEX(Узлы!$B$2:$B$28,MATCH(B9,Узлы!$A$2:$A$28,0)) -> Вынос мусора, мешок | D9: =INDEX(Узлы!$C$2:$C$28,MATCH(B9,Узлы!$A$2:$A$28,0)) -> мешок | E9: 40 | F9: =INDEX(Узлы!$G$2:$G$28,MATCH(B9,Узлы!$A$2:$A$28,0)) -> 2 | G9: =INDEX(Узлы!$E$2:$E$28,MATCH(B9,Узлы!$A$2:$A$28,0)) -> 0.7 | H9: =E9*F9 -> 80 | I9: =E9*G9 -> 28 | J9: =H9+I9 -> 108 | K9: оценка 0,7 мешка на м² при косметическом демонтаже
A10: 4 | B10: N04 | C10: =INDEX(Узлы!$B$2:$B$28,MATCH(B10,Узлы!$A$2:$A$28,0)) -> Вывоз мусора, Газель | D10: =INDEX(Узлы!$C$2:$C$28,MATCH(B10,Узлы!$A$2:$A$28,0)) -> рейс | E10: 1 | F10: =INDEX(Узлы!$G$2:$G$28,MATCH(B10,Узлы!$A$2:$A$28,0)) -> 180 | G10: =INDEX(Узлы!$E$2:$E$28,MATCH(B10,Узлы!$A$2:$A$28,0)) -> 0 | H10: =E10*F10 -> 180 | I10: =E10*G10 -> 0 | J10: =H10+I10 -> 180 | K10: Газель 4–5 м³
C11: Итого по разделу | H11: =SUM(H7:H10) -> 775.37 | I11: =SUM(I7:I10) -> 28 | J11: =SUM(J7:J10) -> 803.37
C13: 2. Перегородки и штукатурка новых стен
A14: 5 | B14: N05 | C14: =INDEX(Узлы!$B$2:$B$28,MATCH(B14,Узлы!$A$2:$A$28,0)) -> Перегородка газосиликат 100 мм | D14: =INDEX(Узлы!$C$2:$C$28,MATCH(B14,Узлы!$A$2:$A$28,0)) -> м² | E14: 12 | F14: =INDEX(Узлы!$G$2:$G$28,MATCH(B14,Узлы!$A$2:$A$28,0)) -> 32 | G14: =INDEX(Узлы!$E$2:$E$28,MATCH(B14,Узлы!$A$2:$A$28,0)) -> 22 | H14: =E14*F14 -> 384 | I14: =E14*G14 -> 264 | J14: =H14+I14 -> 648 | K14: новая перегородка 4,5×2,65 газосиликат 100 мм (пример)
A15: 6 | B15: N07 | C15: =INDEX(Узлы!$B$2:$B$28,MATCH(B15,Узлы!$A$2:$A$28,0)) -> Штукатурка гипсовая 15 мм по маякам (новые перегородки) | D15: =INDEX(Узлы!$C$2:$C$28,MATCH(B15,Узлы!$A$2:$A$28,0)) -> м² | E15: 24 | F15: =INDEX(Узлы!$G$2:$G$28,MATCH(B15,Узлы!$A$2:$A$28,0)) -> 20 | G15: =INDEX(Узлы!$E$2:$E$28,MATCH(B15,Узлы!$A$2:$A$28,0)) -> 9.5 | H15: =E15*F15 -> 480 | I15: =E15*G15 -> 228 | J15: =H15+I15 -> 708 | K15: штукатурка обеих сторон новой перегородки; ПГП/ГКЛ не штукатурятся
A16: 7 | B16: N08 | C16: =INDEX(Узлы!$B$2:$B$28,MATCH(B16,Узлы!$A$2:$A$28,0)) -> Откосы штукатурные | D16: =INDEX(Узлы!$C$2:$C$28,MATCH(B16,Узлы!$A$2:$A$28,0)) -> м.п. | E16: =Объёмы!$K$8 -> 15 | F16: =INDEX(Узлы!$G$2:$G$28,MATCH(B16,Узлы!$A$2:$A$28,0)) -> 18 | G16: =INDEX(Узлы!$E$2:$E$28,MATCH(B16,Узлы!$A$2:$A$28,0)) -> 4.5 | H16: =E16*F16 -> 270 | I16: =E16*G16 -> 67.5 | J16: =H16+I16 -> 337.5 | K16: оконные и дверные откосы
C17: Итого по разделу | H17: =SUM(H14:H16) -> 1134 | I17: =SUM(I14:I16) -> 559.5 | J17: =SUM(J14:J16) -> 1693.5
C19: 3. Шпаклёвка и окраска (стены — по существующей штукатурке, класс «улучшенная», Q3)
A20: 8 | B20: N09 | C20: =INDEX(Узлы!$B$2:$B$28,MATCH(B20,Узлы!$A$2:$A$28,0)) -> Шпаклёвка стен под покраску Q3 (по существующей штукатурке/бетону) | D20: =INDEX(Узлы!$C$2:$C$28,MATCH(B20,Узлы!$A$2:$A$28,0)) -> м² | E20: =Объёмы!$I$9+24 -> 155.99 | F20: =INDEX(Узлы!$G$2:$G$28,MATCH(B20,Узлы!$A$2:$A$28,0)) -> 30 | G20: =INDEX(Узлы!$E$2:$E$28,MATCH(B20,Узлы!$A$2:$A$28,0)) -> 8.3 | H20: =E20*F20 -> 4679.7 | I20: =E20*G20 -> 1294.717 | J20: =H20+I20 -> 5974.417 | K20: существующие стены + новая перегородка после штукатурки
A21: 9 | B21: N10 | C21: =INDEX(Узлы!$B$2:$B$28,MATCH(B21,Узлы!$A$2:$A$28,0)) -> Стеклохолст 40 г/м² на клей | D21: =INDEX(Узлы!$C$2:$C$28,MATCH(B21,Узлы!$A$2:$A$28,0)) -> м² | E21: =Объёмы!$I$9+24+Объёмы!$J$9 -> 204.01 | F21: =INDEX(Узлы!$G$2:$G$28,MATCH(B21,Узлы!$A$2:$A$28,0)) -> 9 | G21: =INDEX(Узлы!$E$2:$E$28,MATCH(B21,Узлы!$A$2:$A$28,0)) -> 3.2 | H21: =E21*F21 -> 1836.09 | I21: =E21*G21 -> 652.832 | J21: =H21+I21 -> 2488.922 | K21: стеклохолст на стены и потолки под покраску
A22: 10 | B22: N11 | C22: =INDEX(Узлы!$B$2:$B$28,MATCH(B22,Узлы!$A$2:$A$28,0)) -> Шпаклёвка потолка под покраску Q3 | D22: =INDEX(Узлы!$C$2:$C$28,MATCH(B22,Узлы!$A$2:$A$28,0)) -> м² | E22: =Объёмы!$J$9 -> 48.02 | F22: =INDEX(Узлы!$G$2:$G$28,MATCH(B22,Узлы!$A$2:$A$28,0)) -> 37 | G22: =INDEX(Узлы!$E$2:$E$28,MATCH(B22,Узлы!$A$2:$A$28,0)) -> 8.3 | H22: =E22*F22 -> 1776.74 | I22: =E22*G22 -> 398.566 | J22: =H22+I22 -> 2175.306 | K22: потолки под покраску; если натяжные — обнулить
A23: 11 | B23: N12 | C23: =INDEX(Узлы!$B$2:$B$28,MATCH(B23,Узлы!$A$2:$A$28,0)) -> Окраска стен 2 слоя + грунт | D23: =INDEX(Узлы!$C$2:$C$28,MATCH(B23,Узлы!$A$2:$A$28,0)) -> м² | E23: =Объёмы!$I$9+24 -> 155.99 | F23: =INDEX(Узлы!$G$2:$G$28,MATCH(B23,Узлы!$A$2:$A$28,0)) -> 10 | G23: =INDEX(Узлы!$E$2:$E$28,MATCH(B23,Узлы!$A$2:$A$28,0)) -> 5.4 | H23: =E23*F23 -> 1559.9 | I23: =E23*G23 -> 842.346 | J23: =H23+I23 -> 2402.246
A24: 12 | B24: N13 | C24: =INDEX(Узлы!$B$2:$B$28,MATCH(B24,Узлы!$A$2:$A$28,0)) -> Окраска потолка 2 слоя + грунт | D24: =INDEX(Узлы!$C$2:$C$28,MATCH(B24,Узлы!$A$2:$A$28,0)) -> м² | E24: =Объёмы!$J$9 -> 48.02 | F24: =INDEX(Узлы!$G$2:$G$28,MATCH(B24,Узлы!$A$2:$A$28,0)) -> 10 | G24: =INDEX(Узлы!$E$2:$E$28,MATCH(B24,Узлы!$A$2:$A$28,0)) -> 5.4 | H24: =E24*F24 -> 480.2 | I24: =E24*G24 -> 259.308 | J24: =H24+I24 -> 739.508
C25: Итого по разделу | H25: =SUM(H20:H24) -> 10332.63 | I25: =SUM(I20:I24) -> 3447.769 | J25: =SUM(J20:J24) -> 13780.399
C27: 4. Полы: самонивелир + клеевой кварцвинил
A28: 13 | B28: N14 | C28: =INDEX(Узлы!$B$2:$B$28,MATCH(B28,Узлы!$A$2:$A$28,0)) -> Подготовка существующей стяжки: шлифовка, пылесос, ремонт трещин | D28: =INDEX(Узлы!$C$2:$C$28,MATCH(B28,Узлы!$A$2:$A$28,0)) -> м² | E28: =Объёмы!$E$9 -> 48.02 | F28: =INDEX(Узлы!$G$2:$G$28,MATCH(B28,Узлы!$A$2:$A$28,0)) -> 4 | G28: =INDEX(Узлы!$E$2:$E$28,MATCH(B28,Узлы!$A$2:$A$28,0)) -> 0.5 | H28: =E28*F28 -> 192.08 | I28: =E28*G28 -> 24.01 | J28: =H28+I28 -> 216.09 | K28: обязательно: CM-тест влажности ≤ 2 %, ровность ≤ 2 мм/2 м — акт
A29: 14 | B29: N15 | C29: =INDEX(Узлы!$B$2:$B$28,MATCH(B29,Узлы!$A$2:$A$28,0)) -> Самонивелир 5 мм с грунтом ×2 и демпфером | D29: =INDEX(Узлы!$C$2:$C$28,MATCH(B29,Узлы!$A$2:$A$28,0)) -> м² | E29: =Объёмы!$E$9 -> 48.02 | F29: =INDEX(Узлы!$G$2:$G$28,MATCH(B29,Узлы!$A$2:$A$28,0)) -> 18 | G29: =INDEX(Узлы!$E$2:$E$28,MATCH(B29,Узлы!$A$2:$A$28,0)) -> 9 | H29: =E29*F29 -> 864.36 | I29: =E29*G29 -> 432.18 | J29: =H29+I29 -> 1296.54 | K29: средняя толщина 5 мм; при перепадах 8–10 мм ×1,6 к материалу
A30: 15 | B30: N16 | C30: =INDEX(Узлы!$B$2:$B$28,MATCH(B30,Узлы!$A$2:$A$28,0)) -> Кварцвинил клеевой, палуба (с запасом 7 %) | D30: =INDEX(Узлы!$C$2:$C$28,MATCH(B30,Узлы!$A$2:$A$28,0)) -> м² | E30: =Объёмы!$E$9 -> 48.02 | F30: =INDEX(Узлы!$G$2:$G$28,MATCH(B30,Узлы!$A$2:$A$28,0)) -> 30 | G30: =INDEX(Узлы!$E$2:$E$28,MATCH(B30,Узлы!$A$2:$A$28,0)) -> 60 | H30: =E30*F30 -> 1440.6 | I30: =E30*G30 -> 2881.2 | J30: =H30+I30 -> 4321.8 | K30: сушка самонивелира 7 суток до укладки
A31: 16 | B31: N17 | C31: =INDEX(Узлы!$B$2:$B$28,MATCH(B31,Узлы!$A$2:$A$28,0)) -> Плинтус МДФ | D31: =INDEX(Узлы!$C$2:$C$28,MATCH(B31,Узлы!$A$2:$A$28,0)) -> м.п. | E31: =Объёмы!$L$9 -> 39.8 | F31: =INDEX(Узлы!$G$2:$G$28,MATCH(B31,Узлы!$A$2:$A$28,0)) -> 19 | G31: =INDEX(Узлы!$E$2:$E$28,MATCH(B31,Узлы!$A$2:$A$28,0)) -> 6.5 | H31: =E31*F31 -> 756.2 | I31: =E31*G31 -> 258.7 | J31: =H31+I31 -> 1014.9
A32: 17 | B32: N18 | C32: =INDEX(Узлы!$B$2:$B$28,MATCH(B32,Узлы!$A$2:$A$28,0)) -> Порожек | D32: =INDEX(Узлы!$C$2:$C$28,MATCH(B32,Узлы!$A$2:$A$28,0)) -> шт | E32: 4 | F32: =INDEX(Узлы!$G$2:$G$28,MATCH(B32,Узлы!$A$2:$A$28,0)) -> 25 | G32: =INDEX(Узлы!$E$2:$E$28,MATCH(B32,Узлы!$A$2:$A$28,0)) -> 22 | H32: =E32*F32 -> 100 | I32: =E32*G32 -> 88 | J32: =H32+I32 -> 188 | K32: порожки в дверных проёмах
C33: Итого по разделу | H33: =SUM(H28:H32) -> 3353.24 | I33: =SUM(I28:I32) -> 3684.09 | J33: =SUM(J28:J32) -> 7037.33
C35: 5. Электрика
A36: 18 | B36: N19 | C36: =INDEX(Узлы!$B$2:$B$28,MATCH(B36,Узлы!$A$2:$A$28,0)) -> Электроточка полная (штроба + 6 м кабеля + подрозетник + механизм) | D36: =INDEX(Узлы!$C$2:$C$28,MATCH(B36,Узлы!$A$2:$A$28,0)) -> точка | E36: 45 | F36: =INDEX(Узлы!$G$2:$G$28,MATCH(B36,Узлы!$A$2:$A$28,0)) -> 90 | G36: =INDEX(Узлы!$E$2:$E$28,MATCH(B36,Узлы!$A$2:$A$28,0)) -> 40 | H36: =E36*F36 -> 4050 | I36: =E36*G36 -> 1800 | J36: =H36+I36 -> 5850 | K36: ≈ 0,8 точки на м² квартиры; уточнить по проекту электрики
A37: 19 | B37: N20 | C37: =INDEX(Узлы!$B$2:$B$28,MATCH(B37,Узлы!$A$2:$A$28,0)) -> Щит квартирный 24 модуля, IEK/ABB | D37: =INDEX(Узлы!$C$2:$C$28,MATCH(B37,Узлы!$A$2:$A$28,0)) -> шт | E37: 1 | F37: =INDEX(Узлы!$G$2:$G$28,MATCH(B37,Узлы!$A$2:$A$28,0)) -> 900 | G37: =INDEX(Узлы!$E$2:$E$28,MATCH(B37,Узлы!$A$2:$A$28,0)) -> 700 | H37: =E37*F37 -> 900 | I37: =E37*G37 -> 700 | J37: =H37+I37 -> 1600
C38: Итого по разделу | H38: =SUM(H36:H37) -> 4950 | I38: =SUM(I36:I37) -> 2500 | J38: =SUM(J36:J37) -> 7450
C40: 6. Сантехника и санузел
A41: 20 | B41: N21 | C41: =INDEX(Узлы!$B$2:$B$28,MATCH(B41,Узлы!$A$2:$A$28,0)) -> Точка водоснабжения PPR/PEX | D41: =INDEX(Узлы!$C$2:$C$28,MATCH(B41,Узлы!$A$2:$A$28,0)) -> точка | E41: 8 | F41: =INDEX(Узлы!$G$2:$G$28,MATCH(B41,Узлы!$A$2:$A$28,0)) -> 70 | G41: =INDEX(Узлы!$E$2:$E$28,MATCH(B41,Узлы!$A$2:$A$28,0)) -> 20 | H41: =E41*F41 -> 560 | I41: =E41*G41 -> 160 | J41: =H41+I41 -> 720 | K41: ХВС/ГВС: раковина, ванна/душ, унитаз, стиральная, кухня
A42: 21 | B42: N22 | C42: =INDEX(Узлы!$B$2:$B$28,MATCH(B42,Узлы!$A$2:$A$28,0)) -> Точка канализации | D42: =INDEX(Узлы!$C$2:$C$28,MATCH(B42,Узлы!$A$2:$A$28,0)) -> точка | E42: 4 | F42: =INDEX(Узлы!$G$2:$G$28,MATCH(B42,Узлы!$A$2:$A$28,0)) -> 45 | G42: =INDEX(Узлы!$E$2:$E$28,MATCH(B42,Узлы!$A$2:$A$28,0)) -> 12 | H42: =E42*F42 -> 180 | I42: =E42*G42 -> 48 | J42: =H42+I42 -> 228
A43: 22 | B43: N23 | C43: =INDEX(Узлы!$B$2:$B$28,MATCH(B43,Узлы!$A$2:$A$28,0)) -> Гидроизоляция цементная 2 слоя (CR 65) | D43: =INDEX(Узлы!$C$2:$C$28,MATCH(B43,Узлы!$A$2:$A$28,0)) -> м² | E43: 6 | F43: =INDEX(Узлы!$G$2:$G$28,MATCH(B43,Узлы!$A$2:$A$28,0)) -> 10 | G43: =INDEX(Узлы!$E$2:$E$28,MATCH(B43,Узлы!$A$2:$A$28,0)) -> 8.5 | H43: =E43*F43 -> 60 | I43: =E43*G43 -> 51 | J43: =H43+I43 -> 111 | K43: пол санузла + заход на стены 300 мм
A44: 23 | B44: N24 | C44: =INDEX(Узлы!$B$2:$B$28,MATCH(B44,Узлы!$A$2:$A$28,0)) -> Плитка на стены 30×60 (плитка 30 руб./м²) | D44: =INDEX(Узлы!$C$2:$C$28,MATCH(B44,Узлы!$A$2:$A$28,0)) -> м² | E44: 22 | F44: =INDEX(Узлы!$G$2:$G$28,MATCH(B44,Узлы!$A$2:$A$28,0)) -> 45 | G44: =INDEX(Узлы!$E$2:$E$28,MATCH(B44,Узлы!$A$2:$A$28,0)) -> 37 | H44: =E44*F44 -> 990 | I44: =E44*G44 -> 814 | J44: =H44+I44 -> 1804 | K44: стены санузла; цена плитки 30 руб./м² условная
A45: 24 | B45: N25 | C45: =INDEX(Узлы!$B$2:$B$28,MATCH(B45,Узлы!$A$2:$A$28,0)) -> Керамогранит 60×60 на пол (плитка 55 руб./м²) | D45: =INDEX(Узлы!$C$2:$C$28,MATCH(B45,Узлы!$A$2:$A$28,0)) -> м² | E45: 4 | F45: =INDEX(Узлы!$G$2:$G$28,MATCH(B45,Узлы!$A$2:$A$28,0)) -> 55 | G45: =INDEX(Узлы!$E$2:$E$28,MATCH(B45,Узлы!$A$2:$A$28,0)) -> 66 | H45: =E45*F45 -> 220 | I45: =E45*G45 -> 264 | J45: =H45+I45 -> 484 | K45: пол санузла; керамогранит 55 руб./м² условный
C46: Итого по разделу | H46: =SUM(H41:H45) -> 2010 | I46: =SUM(I41:I45) -> 1337 | J46: =SUM(J41:J45) -> 3347
...

Sheet Параметры
A1: Параметры расчёта
A2: Показатель | B2: Значение | C2: Источник / пояснение
A3: Курс НБ РБ, BYN за € | B3: 3.4487 | C3: api.nbrb.by, 27.09.2026. Для справочного евро-эквивалента.
A4: Запас на смеси и штучные материалы | B4: 0.1 | C4: Практика: смеси 5–10 %, холст 10 %. Применяется к строке «Материалы» сметы.
A5: Запас на напольное покрытие (LVT палуба) | B5: 0.07 | C5: 5–7 % палуба, 10–12 % ёлка/диагональ. Уже учтён в цене материала узла LVT.
A6: Непредвиденные, % от работ и материалов | B6: 0.05 | C6: Официально 1,5 % (пост. № 116 п. 33.5, текущий ремонт); вторичка 5–10 %.
A7: Накладные и прибыль подрядчика, % от работ | B7: 0.2 | C7: Компании 15–30 % к работам; бригады 0–10 %. Официально ОХР 83,83 % + ПП 45,82 %×1,115 от ФОТ (пост. № 146).
A8: Доставка и подъём материалов, BYN (фикс) | B8: 400 | C8: Газель 160–220/рейс, подъём 1–1,7 руб./место·этаж без лифта.
A9: Стоимость чел.-ч 4 разряда (пост. № 145), BYN | B9: 16.96 | C9: С 01.01.2026. Справочно для ресурсного расчёта.
A10: Полная «официальная» стоимость чел.-ч, BYN | B10: =B8*(1+0.8383+0.4582*1.115+0.34) -> 1075.6772 | C10: 16,96 × (1 + ОХР 83,83 % + ПП 45,82 %×1,115 + страховые 34 %) ≈ 45,6.
A12: Жёлтые ячейки с синим шрифтом — ввод. Чёрные — формулы, зелёные — ссылки на другой лист.

Sheet Ставки
A1: Код | B1: Раздел | C1: Работа | D1: Ед. | E1: Мин | F1: Типично | G1: Макс | H1: С материалом | I1: Примечание
A2: D01 | B2: демонтаж | C2: Перегородка кирпич 1/2 | D2: м2 | E2: 8 | F2: 14 | G2: 45 | H2: нет
A3: D02 | B3: демонтаж | C3: Перегородка ГКЛ | D3: м2 | E3: 3 | F3: 12 | G3: 25 | H3: нет
A4: D03 | B4: демонтаж | C4: Перегородка ж/б, бетон | D4: м2 | E4: 15 | F4: 28 | G4: 40 | H4: нет
A5: D04 | B5: демонтаж | C5: Перегородка блоки (ГСБ, керамзит) | D5: м2 | E5: 12 | F5: 15 | G5: 45 | H5: нет
A6: D05 | B6: демонтаж | C6: Стяжка до 5 см | D6: м2 | E6: 7 | F6: 11 | G6: 30 | H6: нет
A7: D06 | B7: демонтаж | C7: Стяжка 5–10 см | D7: м2 | E7: 12 | F7: 16 | G7: 35 | H7: нет
A8: D07 | B8: демонтаж | C8: Плитка стены/пол с клеем | D8: м2 | E8: 4 | F8: 13 | G8: 20 | H8: нет
A9: D08 | B9: демонтаж | C9: Штукатурка | D9: м2 | E9: 4 | F9: 11 | G9: 15 | H9: нет
A10: D09 | B10: демонтаж | C10: Обои | D10: м2 | E10: 1.5 | F10: 3 | G10: 5 | H10: нет
A11: D10 | B11: демонтаж | C11: Краска/старая шпаклёвка | D11: м2 | E11: 4.5 | F11: 10 | G11: 15.5 | H11: нет
A12: D11 | B12: демонтаж | C12: Дверной блок | D12: шт | E12: 10 | F12: 20 | G12: 40 | H12: нет
A13: D12 | B13: демонтаж | C13: Ванна чугунная | D13: шт | E13: 30 | F13: 50 | G13: 133 | H13: нет
... A47: F02 | B47: полы | C47: Стяжка ЦПС с материалом (>100 м2) | D47: м2 | E47: 17.5 | F47: 18 | G47: 18.5 | H47: да
A48: F03 | B48: полы | C48: Полусухая стяжка механизированная | D48: м2 | E48: 11 | F48: 17.5 | G48: 50 | H48: частично | I48: 17,5 — с материалом на большом объёме
A49: F04 | B49: полы | C49: Наливной пол / самонивелир до 15 мм | D49: м2 | E49: 14 | F49: 18 | G49: 29 | H49: нет
A50: F05 | B50: полы | C50: Гидроизоляция обмазочная 2 слоя | D50: м2 | E50: 7.5 | F50: 10 | G50: 13.3 | H50: нет
A51: F06 | B51: полы | C51: Тёплый пол мат | D51: м2 | E51: 15 | F51: 22 | G51: 60 | H51: нет
A52: F07 | B52: полы | C52: Тёплый пол кабель | D52: м2 | E52: 30 | F52: 44 | G52: 60 | H52: нет | I52: оценка
A53: F08 | B53: полы | C53: Тёплый пол водяной (трубы без стяжки) | D53: м2 | E53: 13 | F53: 25 | G53: 40 | H53: нет
A54: F09 | B54: полы | C54: Плитка керамическая стандарт | D54: м2 | E54: 25 | F54: 45 | G54: 70 | H54: нет
A55: F10 | B55: полы | C55: Керамогранит средний формат | D55: м2 | E55: 35 | F55: 55 | G55: 95 | H55: нет
A56: F11 | B56: полы | C56: Крупноформат 60×120+ | D56: м2 | E56: 45 | F56: 65 | G56: 120 | H56: нет
A57: F12 | B57: полы | C57: Плитка по диагонали | D57: м2 | E57: 35 | F57: 58 | G57: 71 | H57: нет
A58: F13 | B58: полы | C58: Мозаика | D58: м2 | E58: 40 | F58: 80 | G58: 140 | H58: нет
A59: F14 | B59: полы | C59: Ламинат прямо | D59: м2 | E59: 7.5 | F59: 12 | G59: 18 | H59: нет
A60: F15 | B60: полы | C60: Ламинат диагональ | D60: м2 | E60: 10.5 | F60: 15 | G60: 17 | H60: нет
A61: F16 | B61: полы | C61: Кварцвинил/SPC замковый | D61: м2 | E61: 7.5 | F61: 17.5 | G61: 20 | H61: нет
A62: F17 | B62: полы | C62: Кварцвинил клеевой | D62: м2 | E62: 25 | F62: 30 | G62: 39 | H62: нет
A63: F18 | B63: полы | C63: Паркетная доска на клей | D63: м2 | E63: 17 | F63: 40 | G63: 50 | H63: нет
A64: F19 | B64: полы | C64: Плинтус ПВХ | D64: м.п. | E64: 4.5 | F64: 7 | G64: 8 | H64: нет
A65: F20 | B65: полы | C65: Плинтус МДФ/дюрополимер | D65: м.п. | E65: 9 | F65: 19 | G65: 22 | H65: нет
A66: F21 | B66: полы | C66: Плинтус алюминиевый скрытый | D66: м.п. | E66: 25 | F66: 30 | G66: 35 | H66: нет | I66: оценка
A67: F22 | B67: полы | C67: Порожек/компенсационный шов | D67: шт | E67: 15 | F67: 25 | G67: 35 | H67: нет | I67: оценка
A68: E01 | B68: электрика | C68: Штроба бетон | D68: м.п. | E68: 6.5 | F68: 12 | G68: 15 | H68: нет
A69: E02 | B69: электрика | C69: Штроба кирпич | D69: м.п. | E69: 4 | F69: 8 | G69: 10 | H69: нет
A70: E03 | B70: электрика | C70: Штроба газосиликат | D70: м.п. | E70: 1.5 | F70: 5 | G70: 6 | H70: нет
A71: E04 | B71: электрика | C71: Прокладка кабеля 1,5–2,5 | D71: м.п. | E71: 2.2 | F71: 3.3 | G71: 8 | H71: нет
A72: E05 | B72: электрика | C72: Подрозетник (гнездо + монтаж, бетон) | D72: шт | E72: 3.5 | F72: 17 | G72: 19 | H72: нет
A73: E06 | B73: электрика | C73: Розетка/выключатель механизм | D73: шт | E73: 3.6 | F73: 8 | G73: 15 | H73: нет
...

Sheet Узлы
A1: Код узла | B1: Узел | C1: Ед. | D1: Состав и расход на единицу | E1: Материал, BYN/ед. | F1: Код ставки работы | G1: Работа, BYN/ед. | H1: Источник цен
A2: N01 | B2: Демонтаж обоев | C2: м² | D2: вода, размывка; без материала | E2: 0 | F2: D09 | G2: =INDEX(Ставки!$F$2:$F$139,MATCH(F2,Ставки!$A$2:$A$139,0)) -> 3 | H2: розница Минск 27.09.2026, 02-цены-материалы.md
A3: N02 | B3: Демонтаж плинтуса | C3: м.п. | D3: без материала | E3: 0 | F3: ввод | G3: 3 | H3: розница Минск 27.09.2026, 02-цены-материалы.md
A4: N03 | B4: Вынос мусора, мешок | C4: мешок | D4: мешок 0,6–0,8 руб. | E4: 0.7 | F4: D15 | G4: =INDEX(Ставки!$F$2:$F$139,MATCH(F4,Ставки!$A$2:$A$139,0)) -> 2 | H4: розница Минск 27.09.2026, 02-цены-материалы.md
A5: N04 | B5: Вывоз мусора, Газель | C5: рейс | D5: услуга с грузчиками | E5: 0 | F5: D16 | G5: =INDEX(Ставки!$F$2:$F$139,MATCH(F5,Ставки!$A$2:$A$139,0)) -> 180 | H5: розница Минск 27.09.2026, 02-цены-материалы.md
A6: N05 | B6: Перегородка газосиликат 100 мм | C6: м² | D6: 6,4 блока (0,1 м³ × 174 поддоном) + клей 3 кг × 0,42 + анкеры, сетка | E6: 22 | F6: W15 | G6: =INDEX(Ставки!$F$2:$F$139,MATCH(F6,Ставки!$A$2:$A$139,0)) -> 32 | H6: розница Минск 27.09.2026, 02-цены-материалы.md
A7: N06 | B7: Перегородка ПГП 80 мм | C7: м² | D7: 3 плиты × 15,35 + клей 1,5 кг + прокладка, анкеры | E7: 49 | F7: W16 | G7: =INDEX(Ставки!$F$2:$F$139,MATCH(F7,Ставки!$A$2:$A$139,0)) -> 37 | H7: розница Минск 27.09.2026, 02-цены-материалы.md
A8: N07 | B8: Штукатурка гипсовая 15 мм по маякам (новые перегородки) | C8: м² | D8: Rotband/ilmax 12,8 кг × 0,63 + грунт 0,12 кг + маяки 0,9 м + сетка на стыках 0,2 м² | E8: 9.5 | F8: W01 | G8: =INDEX(Ставки!$F$2:$F$139,MATCH(F8,Ставки!$A$2:$A$139,0)) -> 20 | H8: розница Минск 27.09.2026, 02-цены-материалы.md
A9: N08 | B9: Откосы штукатурные | C9: м.п. | D9: смесь ≈ 4 кг + уголок 1 м | E9: 4.5 | F9: C07 | G9: =INDEX(Ставки!$F$2:$F$139,MATCH(F9,Ставки!$A$2:$A$139,0)) -> 18 | H9: розница Минск 27.09.2026, 02-цены-материалы.md
A10: N09 | B10: Шпаклёвка стен под покраску Q3 (по существующей штукатурке/бетону) | C10: м² | D10: старт 2,2 кг × 1,0 + финиш 1,1 кг × 1,5 + грунт 0,4 кг × 4 + сетка стыков 0,3 м² + шкурка 0,12 м² | E10: 8.3 | F10: W09 | G10: =INDEX(Ставки!$F$2:$F$139,MATCH(F10,Ставки!$A$2:$A$139,0)) -> 30 | H10: розница Минск 27.09.2026, 02-цены-материалы.md
A11: N10 | B11: Стеклохолст 40 г/м² на клей | C11: м² | D11: холст 1,1 м² × 1,5 + клей 0,25 кг × 6 | E11: 3.2 | F11: W07 | G11: =INDEX(Ставки!$F$2:$F$139,MATCH(F11,Ставки!$A$2:$A$139,0)) -> 9 | H11: розница Минск 27.09.2026, 02-цены-материалы.md
A12: N11 | B12: Шпаклёвка потолка под покраску Q3 | C12: м² | D12: как N09, труд ×1,17 | E12: 8.3 | F12: ввод | G12: 37 | H12: розница Минск 27.09.2026, 02-цены-материалы.md
A13: N12 | B13: Окраска стен 2 слоя + грунт | C13: м² | D13: краска 0,3 л × 15 (Alpina/Condor) + грунт 0,1 л × 4 + скотч, плёнка | E13: 5.4 | F13: X01 | G13: =INDEX(Ставки!$F$2:$F$139,MATCH(F13,Ставки!$A$2:$A$139,0)) -> 10 | H13: розница Минск 27.09.2026, 02-цены-материалы.md
A14: N13 | B14: Окраска потолка 2 слоя + грунт | C14: м² | D14: как N12 | E14: 5.4 | F14: X02 | G14: =INDEX(Ставки!$F$2:$F$139,MATCH(F14,Ставки!$A$2:$A$139,0)) -> 10 | H14: розница Минск 27.09.2026, 02-цены-материалы.md
A15: N14 | B15: Подготовка существующей стяжки: шлифовка, пылесос, ремонт трещин | C15: м² | D15: ремсостав, диски ≈ 0,5 | E15: 0.5 | F15: ввод | G15: 4 | H15: розница Минск 27.09.2026, 02-цены-материалы.md
A16: N15 | B16: Самонивелир 5 мм с грунтом ×2 и демпфером | C16: м² | D16: смесь 9,5 кг × 0,8 (CN 68 / ilmax 6705) + грунт 0,25 кг × 4 + демпферная лента | E16: 9 | F16: F04 | G16: =INDEX(Ставки!$F$2:$F$139,MATCH(F16,Ставки!$A$2:$A$139,0)) -> 18 | H16: розница Минск 27.09.2026, 02-цены-материалы.md
A17: N16 | B17: Кварцвинил клеевой, палуба (с запасом 7 %) | C17: м² | D17: LVT 53 × 1,07 (Alpine Floor 48–51, FineFloor 59) + клей 0,3 кг × 10 (оценка) | E17: 60 | F17: F17 | G17: =INDEX(Ставки!$F$2:$F$139,MATCH(F17,Ставки!$A$2:$A$139,0)) -> 30 | H17: розница Минск 27.09.2026, 02-цены-материалы.md
A18: N17 | B18: Плинтус МДФ | C18: м.п. | D18: 1,05 м × 5,5 + крепёж, герметик | E18: 6.5 | F18: F20 | G18: =INDEX(Ставки!$F$2:$F$139,MATCH(F18,Ставки!$A$2:$A$139,0)) -> 19 | H18: розница Минск 27.09.2026, 02-цены-материалы.md
A19: N18 | B19: Порожек | C19: шт | D19: алюминиевый порожек 15–30 | E19: 22 | F19: F22 | G19: =INDEX(Ставки!$F$2:$F$139,MATCH(F19,Ставки!$A$2:$A$139,0)) -> 25 | H19: розница Минск 27.09.2026, 02-цены-материалы.md
A20: N19 | B20: Электроточка полная (штроба + 6 м кабеля + подрозетник + механизм) | C20: точка | D20: ВВГнг-LS 6 м × 4 + гофра 6 м × 0,55 + подрозетник 1 + механизм 10 | E20: 40 | F20: E18 | G20: =INDEX(Ставки!$F$2:$F$139,MATCH(F20,Ставки!$A$2:$A$139,0)) -> 90 | H20: розница Минск 27.09.2026, 02-цены-материалы.md
A21: N20 | B21: Щит квартирный 24 модуля, IEK/ABB | C21: шт | D21: корпус 58 + 12 автоматов × 7–24 + 4 УЗО/дифа × 54–168 | E21: 700 | F21: E12 | G21: =INDEX(Ставки!$F$2:$F$139,MATCH(F21,Ставки!$A$2:$A$139,0)) -> 900 | H21: розница Минск 27.09.2026, 02-цены-материалы.md
A22: N21 | B22: Точка водоснабжения PPR/PEX | C22: точка | D22: труба 3–4 м + фитинги + кран | E22: 20 | F22: S01 | G22: =INDEX(Ставки!$F$2:$F$139,MATCH(F22,Ставки!$A$2:$A$139,0)) -> 70 | H22: розница Минск 27.09.2026, 02-цены-материалы.md
A23: N22 | B23: Точка канализации | C23: точка | D23: труба 50 2 м × 4,2 + фитинги | E23: 12 | F23: S02 | G23: =INDEX(Ставки!$F$2:$F$139,MATCH(F23,Ставки!$A$2:$A$139,0)) -> 45 | H23: розница Минск 27.09.2026, 02-цены-материалы.md
A24: N23 | B24: Гидроизоляция цементная 2 слоя (CR 65) | C24: м² | D24: 3 кг × 1,84 + лента 0,6 м × 5 | E24: 8.5 | F24: F05 | G24: =INDEX(Ставки!$F$2:$F$139,MATCH(F24,Ставки!$A$2:$A$139,0)) -> 10 | H24: розница Минск 27.09.2026, 02-цены-материалы.md
A25: N24 | B25: Плитка на стены 30×60 (плитка 30 руб./м²) | C25: м² | D25: клей 4 кг × 0,6 + затирка 0,4 кг × 5 + грунт + плитка 30 × 1,08 | E25: 37 | F25: F09 | G25: =INDEX(Ставки!$F$2:$F$139,MATCH(F25,Ставки!$A$2:$A$139,0)) -> 45 | H25: розница Минск 27.09.2026, 02-цены-материалы.md
A26: N25 | B26: Керамогранит 60×60 на пол (плитка 55 руб./м²) | C26: м² | D26: клей 5 кг × 0,6 + затирка 0,5 кг × 5 + СВП + грунт + плитка 55 × 1,08 | E26: 66 | F26: F10 | G26: =INDEX(Ставки!$F$2:$F$139,MATCH(F26,Ставки!$A$2:$A$139,0)) -> 55 | H26: розница Минск 27.09.2026, 02-цены-материалы.md
A27: N26 | B27: Дверь межкомнатная, установка блока | C27: шт | D27: пена, крепёж ≈ 15; само полотно с коробкой 232–890 — отдельной строкой | E27: 15 | F27: X10 | G27: =INDEX(Ставки!$F$2:$F$139,MATCH(F27,Ставки!$A$2:$A$139,0)) -> 118 | H27: розница Минск 27.09.2026, 02-цены-материалы.md
A28: N27 | B28: Уборка после ремонта | C28: м² | D28: услуга | E28: 0 | F28: O04 | G28: =INDEX(Ставки!$F$2:$F$139,MATCH(F28,Ставки!$A$2:$A$139,0)) -> 4.5 | H28: розница Минск 27.09.2026, 02-цены-материалы.md
A30: Материал на единицу — расчёт по розничным ценам и расходу из техкарт (04-техкарты-узлов.md), без запаса. Запас добавляется в смете параметром. Цены плитки и LVT в составе — условные, замените на выбранные.

Sheet Объёмы
A1: Ведомость объёмов по помещениям (пример — квартира 55 м², высота 2,65; замените на свои замеры)
A2: Помещение | B2: Длина, м | C2: Ширина, м | D2: Высота, м | E2: Пол, м² | F2: Периметр, м | G2: Стены брутто, м² | H2: Проёмы, м² | I2: Стены нетто, м² | J2: Потолок, м² | K2: Откосы, м.п. | L2: Плинтус, м.п. | M2: Примечание
A3: Гостиная | B3: 5.2 | C3: 3.6 | D3: 2.65 | E3: =B3*C3 -> 18.72 | F3: =2*(B3+C3) -> 17.6 | G3: =F3*D3 -> 46.64 | H3: 3.6 | I3: =G3-H3 -> 43.04 | J3: =E3 -> 18.72 | K3: 5 | L3: =F3-4.6 -> 13 | M3: стены шпаклёвка, пол LVT
A4: Спальня | B4: 4 | C4: 3.2 | D4: 2.65 | E4: =B4*C4 -> 12.8 | F4: =2*(B4+C4) -> 14.4 | G4: =F4*D4 -> 38.16 | H4: 3.6 | I4: =G4-H4 -> 34.56 | J4: =E4 -> 12.8 | K4: 5 | L4: =F4-4.6 -> 9.8 | M4: стены шпаклёвка, пол LVT
A5: Кухня | B5: 3.4 | C5: 3 | D5: 2.65 | E5: =B5*C5 -> 10.2 | F5: =2*(B5+C5) -> 12.8 | G5: =F5*D5 -> 33.92 | H5: 3.6 | I5: =G5-H5 -> 30.32 | J5: =E5 -> 10.2 | K5: 5 | L5: =F5-3.6 -> 9.2 | M5: стены шпаклёвка, пол LVT; фартук отдельно
A6: Коридор | B6: 4.5 | C6: 1.4 | D6: 2.65 | E6: =B6*C6 -> 6.3 | F6: =2*(B6+C6) -> 11.8 | G6: =F6*D6 -> 31.27 | H6: 7.2 | I6: =G6-H6 -> 24.07 | J6: =E6 -> 6.3 | K6: 0 | L6: =F6-4.0 -> 7.8 | M6: четыре дверных проёма
A7: Санузел | B7: 2.2 | C7: 1.8 | D7: 2.65 | E7: =B7*C7 -> 3.96 | F7: =2*(B7+C7) -> 8 | G7: =F7*D7 -> 21.2 | H7: 1.6 | I7: =G7-H7 -> 19.6 | J7: =E7 -> 3.96 | K7: 0 | L7: =F7-0 -> 8 | M7: стены плитка, пол керамогранит — считаются в смете отдельно
A8: Итого | E8: =SUM(E3:E7) -> 51.98 | G8: =SUM(G3:G7) -> 171.19 | H8: =SUM(H3:H7) -> 19.6 | I8: =SUM(I3:I7) -> 151.59 | J8: =SUM(J3:J7) -> 51.98 | K8: =SUM(K3:K7) -> 15 | L8: =SUM(L3:L7) -> 47.8
A9: Итого без санузла | E9: =SUM(E3:E6) -> 48.02 | I9: =SUM(I3:I6) -> 131.99 | J9: =SUM(J3:J6) -> 48.02 | L9: =SUM(L3:L6) -> 39.8
A11: Проёмы вычитаются по наружному обводу коробок (окно ≈ 1,5×1,4 = 2,1 м², дверь 0,9×2,1 ≈ 1,9 м²). Откосы считаются отдельно в м.п. Плинтус = периметр минус дверные проёмы. Для микроцемента действуют правила обмера из CLAUDE.md.
