Workbook

Sheet Смета
A1: СМЕТА на ремонт квартиры «под ключ» — ул. Миля 9, Минск
A2: Основание: дизайн-проект Interior AK Design (Хворостов А.О.), 31.07.2026, 49 листов. Заказчики: Юлия и Павел. Площадь 53,88 м² без балкона (57,03 с балконом), высота 2,73 м. Цены — Минск, срез 27.09.2026, BYN без НДС.
A3: Условия просчёта: штукатурятся только новые перегородки, остальные стены шпаклюются; пол — самонивелир 10 мм (по проекту) и клеевой винил Quick-Step Pristine; микроцемент санузла — по модели студии UNICORE. Чистовые материалы заказчика — ориентировочно.
A5: № | B5: Код | C5: Наименование работ и затрат | D5: Ед. | E5: Объём | F5: Работа, BYN/ед. | G5: Материал, BYN/ед. | H5: Работа, BYN | I5: Материал, BYN | J5: Всего, BYN | K5: Основание / примечание
C6: 1. Демонтаж и подготовка
A7: 1 | B7: M01 | C7: =INDEX(Узлы!$B$2:$B$59,MATCH(B7,Узлы!$A$2:$A$59,0)) -> Демонтаж участков перегородок и вырезка проёмов 800/900 (кирпич/блок ~140 мм) | D7: =INDEX(Узлы!$C$2:$C$59,MATCH(B7,Узлы!$A$2:$A$59,0)) -> м² | E7: =Объёмы!$B$11 -> 6.5457 | F7: =INDEX(Узлы!$G$2:$G$59,MATCH(B7,Узлы!$A$2:$A$59,0)) -> 14 | G7: =INDEX(Узлы!$E$2:$E$59,MATCH(B7,Узлы!$A$2:$A$59,0)) -> 0 | H7: =E7*F7 -> 91.6398 | I7: =E7*G7 -> 0 | J7: =H7+I7 -> 91.6398 | K7: лист 3–4
A8: 2 | B8: M02 | C8: =INDEX(Узлы!$B$2:$B$59,MATCH(B8,Узлы!$A$2:$A$59,0)) -> Демонтаж радиаторов | D8: =INDEX(Узлы!$C$2:$C$59,MATCH(B8,Узлы!$A$2:$A$59,0)) -> шт | E8: 2 | F8: =INDEX(Узлы!$G$2:$G$59,MATCH(B8,Узлы!$A$2:$A$59,0)) -> 30 | G8: =INDEX(Узлы!$E$2:$E$59,MATCH(B8,Узлы!$A$2:$A$59,0)) -> 0 | H8: =E8*F8 -> 60 | I8: =E8*G8 -> 0 | J8: =H8+I8 -> 60 | K8: лист 3
A9: 3 | B9: M03 | C9: =INDEX(Узлы!$B$2:$B$59,MATCH(B9,Узлы!$A$2:$A$59,0)) -> Демонтаж эл. щитка с переносом (ниша в стене h=1500) | D9: =INDEX(Узлы!$C$2:$C$59,MATCH(B9,Узлы!$A$2:$A$59,0)) -> шт | E9: 1 | F9: =INDEX(Узлы!$G$2:$G$59,MATCH(B9,Узлы!$A$2:$A$59,0)) -> 150 | G9: =INDEX(Узлы!$E$2:$E$59,MATCH(B9,Узлы!$A$2:$A$59,0)) -> 30 | H9: =E9*F9 -> 150 | I9: =E9*G9 -> 30 | J9: =H9+I9 -> 180 | K9: лист 3–4, перенос щитка
A10: 4 | B10: M04 | C10: =INDEX(Узлы!$B$2:$B$59,MATCH(B10,Узлы!$A$2:$A$59,0)) -> Вынос мусора, мешок | D10: =INDEX(Узлы!$C$2:$C$59,MATCH(B10,Узлы!$A$2:$A$59,0)) -> мешок | E10: 60 | F10: =INDEX(Узлы!$G$2:$G$59,MATCH(B10,Узлы!$A$2:$A$59,0)) -> 2 | G10: =INDEX(Узлы!$E$2:$E$59,MATCH(B10,Узлы!$A$2:$A$59,0)) -> 0.7 | H10: =E10*F10 -> 120 | I10: =E10*G10 -> 42 | J10: =H10+I10 -> 162 | K10: оценка: блоки, штробы, упаковка
A11: 5 | B11: M05 | C11: =INDEX(Узлы!$B$2:$B$59,MATCH(B11,Узлы!$A$2:$A$59,0)) -> Контейнер 8 м³ / Газель | D11: =INDEX(Узлы!$C$2:$C$59,MATCH(B11,Узлы!$A$2:$A$59,0)) -> рейс | E11: 2 | F11: =INDEX(Узлы!$G$2:$G$59,MATCH(B11,Узлы!$A$2:$A$59,0)) -> 180 | G11: =INDEX(Узлы!$E$2:$E$59,MATCH(B11,Узлы!$A$2:$A$59,0)) -> 0 | H11: =E11*F11 -> 360 | I11: =E11*G11 -> 0 | J11: =H11+I11 -> 360 | K11: оценка
C12: Итого по разделу | H12: =SUM(H7:H11) -> 781.6398 | I12: =SUM(I7:I11) -> 72 | J12: =SUM(J7:J11) -> 853.6398
C14: 2. Перегородки и конструкции
A15: 6 | B15: M06 | C15: =INDEX(Узлы!$B$2:$B$59,MATCH(B15,Узлы!$A$2:$A$59,0)) -> Перегородка керамзитобетон 120 мм | D15: =INDEX(Узлы!$C$2:$C$59,MATCH(B15,Узлы!$A$2:$A$59,0)) -> м² | E15: =Объёмы!$B$12 -> 5.5 | F15: =INDEX(Узлы!$G$2:$G$59,MATCH(B15,Узлы!$A$2:$A$59,0)) -> 36 | G15: =INDEX(Узлы!$E$2:$E$59,MATCH(B15,Узлы!$A$2:$A$59,0)) -> 44 | H15: =E15*F15 -> 198 | I15: =E15*G15 -> 242 | J15: =H15+I15 -> 440 | K15: лист 4
A16: 7 | B16: M07 | C16: =INDEX(Узлы!$B$2:$B$59,MATCH(B16,Узлы!$A$2:$A$59,0)) -> Перегородка керамзитобетон 100 мм | D16: =INDEX(Узлы!$C$2:$C$59,MATCH(B16,Узлы!$A$2:$A$59,0)) -> м² | E16: =Объёмы!$B$13 -> 11.67 | F16: =INDEX(Узлы!$G$2:$G$59,MATCH(B16,Узлы!$A$2:$A$59,0)) -> 36 | G16: =INDEX(Узлы!$E$2:$E$59,MATCH(B16,Узлы!$A$2:$A$59,0)) -> 38 | H16: =E16*F16 -> 420.12 | I16: =E16*G16 -> 443.46 | J16: =H16+I16 -> 863.58 | K16: лист 4
A17: 8 | B17: M08 | C17: =INDEX(Узлы!$B$2:$B$59,MATCH(B17,Узлы!$A$2:$A$59,0)) -> Перемычка над проёмом 900 в новой перегородке | D17: =INDEX(Узлы!$C$2:$C$59,MATCH(B17,Узлы!$A$2:$A$59,0)) -> шт | E17: 1 | F17: =INDEX(Узлы!$G$2:$G$59,MATCH(B17,Узлы!$A$2:$A$59,0)) -> 60 | G17: =INDEX(Узлы!$E$2:$E$59,MATCH(B17,Узлы!$A$2:$A$59,0)) -> 40 | H17: =E17*F17 -> 60 | I17: =E17*G17 -> 40 | J17: =H17+I17 -> 100 | K17: проём 900 в перегородке детской
A18: 9 | B18: M09 | C18: =INDEX(Узлы!$B$2:$B$59,MATCH(B18,Узлы!$A$2:$A$59,0)) -> Короб ГКЛВ инсталляции h=1200 и зашивки стояков | D18: =INDEX(Узлы!$C$2:$C$59,MATCH(B18,Узлы!$A$2:$A$59,0)) -> м.п. | E18: 3 | F18: =INDEX(Узлы!$G$2:$G$59,MATCH(B18,Узлы!$A$2:$A$59,0)) -> 160 | G18: =INDEX(Узлы!$E$2:$E$59,MATCH(B18,Узлы!$A$2:$A$59,0)) -> 45 | H18: =E18*F18 -> 480 | I18: =E18*G18 -> 135 | J18: =H18+I18 -> 615 | K18: лист 6–7: короб инсталляции 1,2 м + зашивки, оценка 3 м.п.
A19: 10 | B19: M10 | C19: =INDEX(Узлы!$B$2:$B$59,MATCH(B19,Узлы!$A$2:$A$59,0)) -> Люк ревизионный скрытый под плитку/микроцемент | D19: =INDEX(Узлы!$C$2:$C$59,MATCH(B19,Узлы!$A$2:$A$59,0)) -> шт | E19: 1 | F19: =INDEX(Узлы!$G$2:$G$59,MATCH(B19,Узлы!$A$2:$A$59,0)) -> 110 | G19: =INDEX(Узлы!$E$2:$E$59,MATCH(B19,Узлы!$A$2:$A$59,0)) -> 120 | H19: =E19*F19 -> 110 | I19: =E19*G19 -> 120 | J19: =H19+I19 -> 230 | K19: доступ к инсталляции/коллекторам
C20: Итого по разделу | H20: =SUM(H15:H19) -> 1268.12 | I20: =SUM(I15:I19) -> 980.46 | J20: =SUM(J15:J19) -> 2248.58
C22: 3. Штукатурка новых стен, шпаклёвка существующих
A23: 11 | B23: M11 | C23: =INDEX(Узлы!$B$2:$B$59,MATCH(B23,Узлы!$A$2:$A$59,0)) -> Штукатурка гипсовая по маякам 15 мм — ТОЛЬКО новые перегородки (обе стороны) | D23: =INDEX(Узлы!$C$2:$C$59,MATCH(B23,Узлы!$A$2:$A$59,0)) -> м² | E23: =Объёмы!$B$14 -> 32.45 | F23: =INDEX(Узлы!$G$2:$G$59,MATCH(B23,Узлы!$A$2:$A$59,0)) -> 20 | G23: =INDEX(Узлы!$E$2:$E$59,MATCH(B23,Узлы!$A$2:$A$59,0)) -> 9.5 | H23: =E23*F23 -> 649 | I23: =E23*G23 -> 308.275 | J23: =H23+I23 -> 957.275 | K23: только возведённые стены
A24: 12 | B24: M12 | C24: =INDEX(Узлы!$B$2:$B$59,MATCH(B24,Узлы!$A$2:$A$59,0)) -> Откосы окон и балконной двери: штукатурка + шпаклёвка + покраска | D24: =INDEX(Узлы!$C$2:$C$59,MATCH(B24,Узлы!$A$2:$A$59,0)) -> м.п. | E24: =Объёмы!$B$24 -> 20 | F24: =INDEX(Узлы!$G$2:$G$59,MATCH(B24,Узлы!$A$2:$A$59,0)) -> 45 | G24: =INDEX(Узлы!$E$2:$E$59,MATCH(B24,Узлы!$A$2:$A$59,0)) -> 8 | H24: =E24*F24 -> 900 | I24: =E24*G24 -> 160 | J24: =H24+I24 -> 1060 | K24: оценка 20 м.п.
A25: 13 | B25: M13 | C25: =INDEX(Узлы!$B$2:$B$59,MATCH(B25,Узлы!$A$2:$A$59,0)) -> Шпаклёвка Q3 по существующим стенам под покраску и декоративную штукатурку | D25: =INDEX(Узлы!$C$2:$C$59,MATCH(B25,Узлы!$A$2:$A$59,0)) -> м² | E25: =Объёмы!$B$22 -> 111 | F25: =INDEX(Узлы!$G$2:$G$59,MATCH(B25,Узлы!$A$2:$A$59,0)) -> 30 | G25: =INDEX(Узлы!$E$2:$E$59,MATCH(B25,Узлы!$A$2:$A$59,0)) -> 8.3 | H25: =E25*F25 -> 3330 | I25: =E25*G25 -> 921.3 | J25: =H25+I25 -> 4251.3 | K25: ДК-1 61 + УСЛ-1 50 м²; класс «улучшенная» на существующих стенах
A26: 14 | B26: M14 | C26: =INDEX(Узлы!$B$2:$B$59,MATCH(B26,Узлы!$A$2:$A$59,0)) -> Стеклохолст 40 г/м² на клей (под покраску и Marmorino) | D26: =INDEX(Узлы!$C$2:$C$59,MATCH(B26,Узлы!$A$2:$A$59,0)) -> м² | E26: =Объёмы!$B$22 -> 111 | F26: =INDEX(Узлы!$G$2:$G$59,MATCH(B26,Узлы!$A$2:$A$59,0)) -> 9 | G26: =INDEX(Узлы!$E$2:$E$59,MATCH(B26,Узлы!$A$2:$A$59,0)) -> 3.2 | H26: =E26*F26 -> 999 | I26: =E26*G26 -> 355.2 | J26: =H26+I26 -> 1354.2 | K26: холст под покраску и Marmorino
A27: 15 | B27: M15 | C27: =INDEX(Узлы!$B$2:$B$59,MATCH(B27,Узлы!$A$2:$A$59,0)) -> Шпаклёвка Q2 под обои и фотообои | D27: =INDEX(Узлы!$C$2:$C$59,MATCH(B27,Узлы!$A$2:$A$59,0)) -> м² | E27: =Объёмы!$B$23 -> 40.95 | F27: =INDEX(Узлы!$G$2:$G$59,MATCH(B27,Узлы!$A$2:$A$59,0)) -> 14 | G27: =INDEX(Узлы!$E$2:$E$59,MATCH(B27,Узлы!$A$2:$A$59,0)) -> 3 | H27: =E27*F27 -> 573.3 | I27: =E27*G27 -> 122.85 | J27: =H27+I27 -> 696.15 | K27: ОБ-1 + ФО
A28: 16 | B28: M16 | C28: =INDEX(Узлы!$B$2:$B$59,MATCH(B28,Узлы!$A$2:$A$59,0)) -> Подготовка стен санузла под микроцемент (цементная шпаклёвка Q3 + грунт) | D28: =INDEX(Узлы!$C$2:$C$59,MATCH(B28,Узлы!$A$2:$A$59,0)) -> м² | E28: =Объёмы!$B$21 -> 18 | F28: =INDEX(Узлы!$G$2:$G$59,MATCH(B28,Узлы!$A$2:$A$59,0)) -> 30 | G28: =INDEX(Узлы!$E$2:$E$59,MATCH(B28,Узлы!$A$2:$A$59,0)) -> 4.5 | H28: =E28*F28 -> 540 | I28: =E28*G28 -> 81 | J28: =H28+I28 -> 621 | K28: цементная шпаклёвка в санузле
C29: Итого по разделу | H29: =SUM(H23:H28) -> 6991.3 | I29: =SUM(I23:I28) -> 1948.625 | J29: =SUM(J23:J28) -> 8939.925
C31: 4. Полы
A32: 17 | B32: M17 | C32: =INDEX(Узлы!$B$2:$B$59,MATCH(B32,Узлы!$A$2:$A$59,0)) -> Подготовка существующей стяжки: шлифовка, пылесос, ремонт трещин, CM-тест | D32: =INDEX(Узлы!$C$2:$C$59,MATCH(B32,Узлы!$A$2:$A$59,0)) -> м² | E32: =Объёмы!$B$26 -> 49 | F32: =INDEX(Узлы!$G$2:$G$59,MATCH(B32,Узлы!$A$2:$A$59,0)) -> 4 | G32: =INDEX(Узлы!$E$2:$E$59,MATCH(B32,Узлы!$A$2:$A$59,0)) -> 0.5 | H32: =E32*F32 -> 196 | I32: =E32*G32 -> 24.5 | J32: =H32+I32 -> 220.5 | K32: протокол CM ≤ 2 % и ровности ≤ 2 мм/2 м — условие гарантии
A33: 18 | B33: M18 | C33: =INDEX(Узлы!$B$2:$B$59,MATCH(B33,Узлы!$A$2:$A$59,0)) -> Самонивелир 10 мм с грунтом ×2 и демпфером (по проекту, лист 14 узел V1) | D33: =INDEX(Узлы!$C$2:$C$59,MATCH(B33,Узлы!$A$2:$A$59,0)) -> м² | E33: =Объёмы!$B$26 -> 49 | F33: =INDEX(Узлы!$G$2:$G$59,MATCH(B33,Узлы!$A$2:$A$59,0)) -> 18 | G33: =INDEX(Узлы!$E$2:$E$59,MATCH(B33,Узлы!$A$2:$A$59,0)) -> 15.6 | H33: =E33*F33 -> 882 | I33: =E33*G33 -> 764.4 | J33: =H33+I33 -> 1646.4 | K33: лист 14: самонивелир 10 мм по проекту
A34: 19 | B34: M19 | C34: =INDEX(Узлы!$B$2:$B$59,MATCH(B34,Узлы!$A$2:$A$59,0)) -> Клеевой винил Quick-Step Pristine, палуба (запас 7 %) | D34: =INDEX(Узлы!$C$2:$C$59,MATCH(B34,Узлы!$A$2:$A$59,0)) -> м² | E34: =Объёмы!$B$25 -> 49 | F34: =INDEX(Узлы!$G$2:$G$59,MATCH(B34,Узлы!$A$2:$A$59,0)) -> 30 | G34: =INDEX(Узлы!$E$2:$E$59,MATCH(B34,Узлы!$A$2:$A$59,0)) -> 62 | H34: =E34*F34 -> 1470 | I34: =E34*G34 -> 3038 | J34: =H34+I34 -> 4508 | K34: лист 14; сушка самонивелира 7 сут
A35: 20 | B35: M20 | C35: =INDEX(Узлы!$B$2:$B$59,MATCH(B35,Узлы!$A$2:$A$59,0)) -> Керамогранит на пол санузла Argenta Westone 120×60 | D35: =INDEX(Узлы!$C$2:$C$59,MATCH(B35,Узлы!$A$2:$A$59,0)) -> м² | E35: =Объёмы!$B$27 -> 4.78 | F35: =INDEX(Узлы!$G$2:$G$59,MATCH(B35,Узлы!$A$2:$A$59,0)) -> 65 | G35: =INDEX(Узлы!$E$2:$E$59,MATCH(B35,Узлы!$A$2:$A$59,0)) -> 160 | H35: =E35*F35 -> 310.7 | I35: =E35*G35 -> 764.8 | J35: =H35+I35 -> 1075.5 | K35: лист 14
A36: 21 | B36: M21 | C36: =INDEX(Узлы!$B$2:$B$59,MATCH(B36,Узлы!$A$2:$A$59,0)) -> Керамогранит у входа Ponza Lilly 200×200 (50 шт) | D36: =INDEX(Узлы!$C$2:$C$59,MATCH(B36,Узлы!$A$2:$A$59,0)) -> м² | E36: =Объёмы!$B$28 -> 2 | F36: =INDEX(Узлы!$G$2:$G$59,MATCH(B36,Узлы!$A$2:$A$59,0)) -> 45 | G36: =INDEX(Узлы!$E$2:$E$59,MATCH(B36,Узлы!$A$2:$A$59,0)) -> 71 | H36: =E36*F36 -> 90 | I36: =E36*G36 -> 142 | J36: =H36+I36 -> 232 | K36: лист 14
A37: 22 | B37: M22 | C37: =INDEX(Узлы!$B$2:$B$59,MATCH(B37,Узлы!$A$2:$A$59,0)) -> Гидроизоляция санузла обмазочная 2 слоя (пол + стены 300 мм + душевая зона) | D37: =INDEX(Узлы!$C$2:$C$59,MATCH(B37,Узлы!$A$2:$A$59,0)) -> м² | E37: =Объёмы!$B$29 -> 13.08 | F37: =INDEX(Узлы!$G$2:$G$59,MATCH(B37,Узлы!$A$2:$A$59,0)) -> 10 | G37: =INDEX(Узлы!$E$2:$E$59,MATCH(B37,Узлы!$A$2:$A$59,0)) -> 8.5 | H37: =E37*F37 -> 130.8 | I37: =E37*G37 -> 111.18 | J37: =H37+I37 -> 241.98 | K37: СН 5.09.01: заход на стены ≥ 300 мм
A38: 23 | B38: M23 | C38: =INDEX(Узлы!$B$2:$B$59,MATCH(B38,Узлы!$A$2:$A$59,0)) -> Тёплый пол электрический Nexans (кабель в санузле и прихожей) | D38: =INDEX(Узлы!$C$2:$C$59,MATCH(B38,Узлы!$A$2:$A$59,0)) -> м² | E38: =Объёмы!$B$30 -> 2.77 | F38: =INDEX(Узлы!$G$2:$G$59,MATCH(B38,Узлы!$A$2:$A$59,0)) -> 44 | G38: =INDEX(Узлы!$E$2:$E$59,MATCH(B38,Узлы!$A$2:$A$59,0)) -> 90 | H38: =E38*F38 -> 121.88 | I38: =E38*G38 -> 249.3 | J38: =H38+I38 -> 371.18 | K38: лист 13 без балкона
A39: 24 | B39: M24 | C39: =INDEX(Узлы!$B$2:$B$59,MATCH(B39,Узлы!$A$2:$A$59,0)) -> Терморегулятор | D39: =INDEX(Узлы!$C$2:$C$59,MATCH(B39,Узлы!$A$2:$A$59,0)) -> шт | E39: 2 | F39: =INDEX(Узлы!$G$2:$G$59,MATCH(B39,Узлы!$A$2:$A$59,0)) -> 50 | G39: =INDEX(Узлы!$E$2:$E$59,MATCH(B39,Узлы!$A$2:$A$59,0)) -> 72 | H39: =E39*F39 -> 100 | I39: =E39*G39 -> 144 | J39: =H39+I39 -> 244 | K39: лист 13: 3 шт, балконный исключён
A40: 25 | B40: M25 | C40: =INDEX(Узлы!$B$2:$B$59,MATCH(B40,Узлы!$A$2:$A$59,0)) -> Плинтус МДФ OHZ HM-1540 | D40: =INDEX(Узлы!$C$2:$C$59,MATCH(B40,Узлы!$A$2:$A$59,0)) -> м.п. | E40: =Объёмы!$B$31 -> 35.19 | F40: =INDEX(Узлы!$G$2:$G$59,MATCH(B40,Узлы!$A$2:$A$59,0)) -> 19 | G40: =INDEX(Узлы!$E$2:$E$59,MATCH(B40,Узлы!$A$2:$A$59,0)) -> 4.5 | H40: =E40*F40 -> 668.61 | I40: =E40*G40 -> 158.355 | J40: =H40+I40 -> 826.965 | K40: лист 26
A41: 26 | B41: M26 | C41: =INDEX(Узлы!$B$2:$B$59,MATCH(B41,Узлы!$A$2:$A$59,0)) -> Порожки / стык LVT–керамогранит через герметик | D41: =INDEX(Узлы!$C$2:$C$59,MATCH(B41,Узлы!$A$2:$A$59,0)) -> шт | E41: 5 | F41: =INDEX(Узлы!$G$2:$G$59,MATCH(B41,Узлы!$A$2:$A$59,0)) -> 25 | G41: =INDEX(Узлы!$E$2:$E$59,MATCH(B41,Узлы!$A$2:$A$59,0)) -> 28 | H41: =E41*F41 -> 125 | I41: =E41*G41 -> 140 | J41: =H41+I41 -> 265 | K41: стыки LVT/керамогранит: вход, санузел, балкон
C42: Итого по разделу | H42: =SUM(H32:H41) -> 4094.99 | I42: =SUM(I32:I41) -> 5536.535 | J42: =SUM(J32:J41) -> 9631.525
C44: 5. Потолки
A45: 27 | B45: M27 | C45: =INDEX(Узлы!$B$2:$B$59,MATCH(B45,Узлы!$A$2:$A$59,0)) -> Натяжной потолок ПВХ матовый, с материалом и монтажом | D45: =INDEX(Узлы!$C$2:$C$59,MATCH(B45,Узлы!$A$2:$A$59,0)) -> м² | E45: =Объёмы!$B$32 -> 45 | F45: =INDEX(Узлы!$G$2:$G$59,MATCH(B45,Узлы!$A$2:$A$59,0)) -> 28 | G45: =INDEX(Узлы!$E$2:$E$59,MATCH(B45,Узлы!$A$2:$A$59,0)) -> 0 | H45: =E45*F45 -> 1260 | I45: =E45*G45 -> 0 | J45: =H45+I45 -> 1260 | K45: лист 17, с материалом
...

Sheet Параметры
A1: Параметры расчёта — Миля 9
A2: Показатель | B2: Значение | C2: Источник / пояснение
A3: Курс НБ РБ, BYN за € | B3: 3.4487 | C3: api.nbrb.by, 27.09.2026. Микроцемент считается по модели студии в €.
A4: Запас на смеси и штучные материалы | B4: 0.1 | C4: Смеси 5–10 %, холст 10 %. К строке «Материалы» сметы (кроме LVT — запас 7 % уже в цене узла).
A5: Запас на LVT (палуба) | B5: 0.07 | C5: Справочно; учтён в узле M17.
A6: Непредвиденные, % от работ и материалов | B6: 0.05 | C6: Официально 1,5 % (пост. № 116); новостройка без отделки 3–5 %.
A7: Накладные и прибыль подрядчика, % от работ | B7: 0.2 | C7: Компании 15–30 %; бригады 0–10 %.
A8: Доставка и подъём материалов, BYN (фикс) | B8: 500 | C8: Газель 160–220/рейс × 2–3 рейса; подъём на этаж.
A9: Стоимость чел.-ч 4 разряда (пост. № 145), BYN | B9: 16.96 | C9: С 01.01.2026, справочно.
A10: Полная «официальная» стоимость чел.-ч, BYN | B10: =B8*(1+0.8383+0.4582*1.115+0.34) -> 1344.5965 | C10: ≈ 45,6 руб. — нижняя граница проверки ставок.
A11: Высота помещений, м | B11: 2.73 | C11: Лист 2 обмера: 2 730 (санузел 2 750), от чернового пола.
A13: Жёлтые ячейки с синим шрифтом — ввод. Чёрные — формулы, зелёные — ссылки на другой лист.

Sheet Ставки
A1: Код | B1: Раздел | C1: Работа | D1: Ед. | E1: Мин | F1: Типично | G1: Макс | H1: С материалом | I1: Примечание
A2: D01 | B2: демонтаж | C2: Перегородка кирпич 1/2 | D2: м2 | E2: 8 | F2: 14 | G2: 45 | H2: нет
A3: D02 | B3: демонтаж | C3: Перегородка ГКЛ | D3: м2 | E3: 3 | F3: 12 | G3: 25 | H3: нет
A4: D03 | B4: демонтаж | C4: Перегородка ж/б, бетон | D4: м2 | E4: 15 | F4: 28 | G4: 40 | H4: нет
A5: D04 | B5: демонтаж | C5: Перегородка блоки (ГСБ, керамзит) | D5: м2 | E5: 12 | F5: 15 | G5: 45 | H5: нет
A6: D05 | B6: демонтаж | C6: Стяжка до 5 см | D6: м2 | E6: 7 | F6: 11 | G6: 30 | H6: нет
A7: D06 | B7: демонтаж | C7: Стяжка 5–10 см | D7: м2 | E7: 12 | F7: 16 | G7: 35 | H7: нет
A8: D07 | B8: демонтаж | C8: Плитка стены/пол с клеем | D8: м2 | E8: 4 | F8: 13 | G8: 20 | H8: нет
A9: D08 | B9: демонтаж | C9: Штукатурка | D9: м2 | E9: 4 | F9: 11 | G9: 15 | H9: нет
A10: D09 | B10: демонтаж | C10: Обои | D10: м2 | E10: 1.5 | F10: 3 | G10: 5 | H10: нет
A11: D10 | B11: демонтаж | C11: Краска/старая шпаклёвка | D11: м2 | E11: 4.5 | F11: 10 | G11: 15.5 | H11: нет
A12: D11 | B12: демонтаж | C12: Дверной блок | D12: шт | E12: 10 | F12: 20 | G12: 40 | H12: нет
A13: D12 | B13: демонтаж | C13: Ванна чугунная | D13: шт | E13: 30 | F13: 50 | G13: 133 | H13: нет
... A47: F02 | B47: полы | C47: Стяжка ЦПС с материалом (>100 м2) | D47: м2 | E47: 17.5 | F47: 18 | G47: 18.5 | H47: да
A48: F03 | B48: полы | C48: Полусухая стяжка механизированная | D48: м2 | E48: 11 | F48: 17.5 | G48: 50 | H48: частично | I48: 17,5 — с материалом на большом объёме
A49: F04 | B49: полы | C49: Наливной пол / самонивелир до 15 мм | D49: м2 | E49: 14 | F49: 18 | G49: 29 | H49: нет
A50: F05 | B50: полы | C50: Гидроизоляция обмазочная 2 слоя | D50: м2 | E50: 7.5 | F50: 10 | G50: 13.3 | H50: нет
A51: F06 | B51: полы | C51: Тёплый пол мат | D51: м2 | E51: 15 | F51: 22 | G51: 60 | H51: нет
A52: F07 | B52: полы | C52: Тёплый пол кабель | D52: м2 | E52: 30 | F52: 44 | G52: 60 | H52: нет | I52: оценка
A53: F08 | B53: полы | C53: Тёплый пол водяной (трубы без стяжки) | D53: м2 | E53: 13 | F53: 25 | G53: 40 | H53: нет
A54: F09 | B54: полы | C54: Плитка керамическая стандарт | D54: м2 | E54: 25 | F54: 45 | G54: 70 | H54: нет
A55: F10 | B55: полы | C55: Керамогранит средний формат | D55: м2 | E55: 35 | F55: 55 | G55: 95 | H55: нет
A56: F11 | B56: полы | C56: Крупноформат 60×120+ | D56: м2 | E56: 45 | F56: 65 | G56: 120 | H56: нет
A57: F12 | B57: полы | C57: Плитка по диагонали | D57: м2 | E57: 35 | F57: 58 | G57: 71 | H57: нет
A58: F13 | B58: полы | C58: Мозаика | D58: м2 | E58: 40 | F58: 80 | G58: 140 | H58: нет
A59: F14 | B59: полы | C59: Ламинат прямо | D59: м2 | E59: 7.5 | F59: 12 | G59: 18 | H59: нет
A60: F15 | B60: полы | C60: Ламинат диагональ | D60: м2 | E60: 10.5 | F60: 15 | G60: 17 | H60: нет
A61: F16 | B61: полы | C61: Кварцвинил/SPC замковый | D61: м2 | E61: 7.5 | F61: 17.5 | G61: 20 | H61: нет
A62: F17 | B62: полы | C62: Кварцвинил клеевой | D62: м2 | E62: 25 | F62: 30 | G62: 39 | H62: нет
A63: F18 | B63: полы | C63: Паркетная доска на клей | D63: м2 | E63: 17 | F63: 40 | G63: 50 | H63: нет
A64: F19 | B64: полы | C64: Плинтус ПВХ | D64: м.п. | E64: 4.5 | F64: 7 | G64: 8 | H64: нет
A65: F20 | B65: полы | C65: Плинтус МДФ/дюрополимер | D65: м.п. | E65: 9 | F65: 19 | G65: 22 | H65: нет
A66: F21 | B66: полы | C66: Плинтус алюминиевый скрытый | D66: м.п. | E66: 25 | F66: 30 | G66: 35 | H66: нет | I66: оценка
A67: F22 | B67: полы | C67: Порожек/компенсационный шов | D67: шт | E67: 15 | F67: 25 | G67: 35 | H67: нет | I67: оценка
A68: E01 | B68: электрика | C68: Штроба бетон | D68: м.п. | E68: 6.5 | F68: 12 | G68: 15 | H68: нет
A69: E02 | B69: электрика | C69: Штроба кирпич | D69: м.п. | E69: 4 | F69: 8 | G69: 10 | H69: нет
A70: E03 | B70: электрика | C70: Штроба газосиликат | D70: м.п. | E70: 1.5 | F70: 5 | G70: 6 | H70: нет
A71: E04 | B71: электрика | C71: Прокладка кабеля 1,5–2,5 | D71: м.п. | E71: 2.2 | F71: 3.3 | G71: 8 | H71: нет
A72: E05 | B72: электрика | C72: Подрозетник (гнездо + монтаж, бетон) | D72: шт | E72: 3.5 | F72: 17 | G72: 19 | H72: нет
A73: E06 | B73: электрика | C73: Розетка/выключатель механизм | D73: шт | E73: 3.6 | F73: 8 | G73: 15 | H73: нет
...

Sheet Узлы
A1: Код | B1: Узел | C1: Ед. | D1: Состав и расход на единицу / основание | E1: Материал, BYN/ед. | F1: Код ставки | G1: Работа, BYN/ед. | H1: Примечание
A2: M01 | B2: Демонтаж участков перегородок и вырезка проёмов 800/900 (кирпич/блок ~140 мм) | C2: м² | D2: лист 3: участки 280+500+260+50 мм × 2,73 + проёмы 0,8×2,1 и 0,9×2,1 | E2: 0 | F2: D01 | G2: =INDEX(Ставки!$F$2:$F$139,MATCH(F2,Ставки!$A$2:$A$139,0)) -> 14
A3: M02 | B3: Демонтаж радиаторов | C3: шт | D3: лист 3: 2 шт (600 и 700) | E3: 0 | F3: D14 | G3: =INDEX(Ставки!$F$2:$F$139,MATCH(F3,Ставки!$A$2:$A$139,0)) -> 30
A4: M03 | B4: Демонтаж эл. щитка с переносом (ниша в стене h=1500) | C4: шт | D4: лист 3–4: щиток утопить в стену; штроба ниши, перенос ввода | E4: 30 | F4: ввод | G4: 150 | H4: оценка
A5: M04 | B5: Вынос мусора, мешок | C5: мешок | D5: 0,6–0,8 руб. мешок | E5: 0.7 | F5: D15 | G5: =INDEX(Ставки!$F$2:$F$139,MATCH(F5,Ставки!$A$2:$A$139,0)) -> 2
A6: M05 | B6: Контейнер 8 м³ / Газель | C6: рейс | D6: блоки, штукатурка 1 800 кг/м³ | E6: 0 | F6: D16 | G6: =INDEX(Ставки!$F$2:$F$139,MATCH(F6,Ставки!$A$2:$A$139,0)) -> 180 | H6: при большом объёме — контейнер 365
A7: M06 | B7: Перегородка керамзитобетон 120 мм | C7: м² | D7: лист 4: S=5,5 м²; блок 510×120×240 ≈ 8,2 шт × 4,96 + клей 3 кг + анкеры, сетка | E7: 44 | F7: W17 | G7: =INDEX(Ставки!$F$2:$F$139,MATCH(F7,Ставки!$A$2:$A$139,0)) -> 36
A8: M07 | B8: Перегородка керамзитобетон 100 мм | C8: м² | D8: лист 4: S=11,67 м²; блок 400×100×240 ≈ 10,4 шт × 3,29 + клей + анкеры | E8: 38 | F8: W17 | G8: =INDEX(Ставки!$F$2:$F$139,MATCH(F8,Ставки!$A$2:$A$139,0)) -> 36
A9: M08 | B9: Перемычка над проёмом 900 в новой перегородке | C9: шт | D9: уголок/брусковая перемычка | E9: 40 | F9: ввод | G9: 60 | H9: оценка
A10: M09 | B10: Короб ГКЛВ инсталляции h=1200 и зашивки стояков | C10: м.п. | D10: лист 6–7: ВГКЛ + профиль ПС/ПН | E10: 45 | F10: S19 | G10: =INDEX(Ставки!$F$2:$F$139,MATCH(F10,Ставки!$A$2:$A$139,0)) -> 160
A11: M10 | B11: Люк ревизионный скрытый под плитку/микроцемент | C11: шт | D11: люк 300×400 ≈ 120 | E11: 120 | F11: T05 | G11: =INDEX(Ставки!$F$2:$F$139,MATCH(F11,Ставки!$A$2:$A$139,0)) -> 110
A12: M11 | B12: Штукатурка гипсовая по маякам 15 мм — ТОЛЬКО новые перегородки (обе стороны) | C12: м² | D12: Rotband/ilmax 12,8 кг × 0,63 + грунт + маяки + сетка на стыках со старыми стенами | E12: 9.5 | F12: W01 | G12: =INDEX(Ставки!$F$2:$F$139,MATCH(F12,Ставки!$A$2:$A$139,0)) -> 20
A13: M12 | B13: Откосы окон и балконной двери: штукатурка + шпаклёвка + покраска | C13: м.п. | D13: 3 окна + балконная дверь; уголок, смесь, шпаклёвка, краска | E13: 8 | F13: C08 | G13: =INDEX(Ставки!$F$2:$F$139,MATCH(F13,Ставки!$A$2:$A$139,0)) -> 45
A14: M13 | B14: Шпаклёвка Q3 по существующим стенам под покраску и декоративную штукатурку | C14: м² | D14: старт 2,2 кг × 1,0 + финиш 1,1 кг × 1,5 + грунт 0,4 кг + сетка стыков + шкурка | E14: 8.3 | F14: W09 | G14: =INDEX(Ставки!$F$2:$F$139,MATCH(F14,Ставки!$A$2:$A$139,0)) -> 30
A15: M14 | B15: Стеклохолст 40 г/м² на клей (под покраску и Marmorino) | C15: м² | D15: холст 1,1 м² × 1,5 + клей 0,25 кг × 6 | E15: 3.2 | F15: W07 | G15: =INDEX(Ставки!$F$2:$F$139,MATCH(F15,Ставки!$A$2:$A$139,0)) -> 9
A16: M15 | B16: Шпаклёвка Q2 под обои и фотообои | C16: м² | D16: старт 1,5 кг + грунт 0,25 кг + шкурка | E16: 3 | F16: W08 | G16: =INDEX(Ставки!$F$2:$F$139,MATCH(F16,Ставки!$A$2:$A$139,0)) -> 14
A17: M16 | B17: Подготовка стен санузла под микроцемент (цементная шпаклёвка Q3 + грунт) | C17: м² | D17: ilmax 6400 цементная 2,5 кг × 1,2 + грунт; санузел, 18 м² | E17: 4.5 | F17: W09 | G17: =INDEX(Ставки!$F$2:$F$139,MATCH(F17,Ставки!$A$2:$A$139,0)) -> 30
A18: M17 | B18: Подготовка существующей стяжки: шлифовка, пылесос, ремонт трещин, CM-тест | C18: м² | D18: ремсостав, диски; протокол влажности | E18: 0.5 | F18: ввод | G18: 4 | H18: оценка
A19: M18 | B19: Самонивелир 10 мм с грунтом ×2 и демпфером (по проекту, лист 14 узел V1) | C19: м² | D19: смесь 1,7 кг/мм × 10 = 17 кг × 0,8 + грунт 0,25 кг × 4 + демпфер | E19: 15.6 | F19: F04 | G19: =INDEX(Ставки!$F$2:$F$139,MATCH(F19,Ставки!$A$2:$A$139,0)) -> 18
A20: M19 | B20: Клеевой винил Quick-Step Pristine, палуба (запас 7 %) | C20: м² | D20: лист 14: 49 м² без запаса; цена LVT ~55 × 1,07 + клей 0,3 кг × 10 (оценка) | E20: 62 | F20: F17 | G20: =INDEX(Ставки!$F$2:$F$139,MATCH(F20,Ставки!$A$2:$A$139,0)) -> 30 | H20: цену Quick-Step уточнить у alexparket/ecopol
A21: M20 | B21: Керамогранит на пол санузла Argenta Westone 120×60 | C21: м² | D21: клей C2 6 кг × 0,8 + затирка эпокси 0,4 кг × 70 + СВП; плитка ~110 × 1,1 | E21: 160 | F21: F11 | G21: =INDEX(Ставки!$F$2:$F$139,MATCH(F21,Ставки!$A$2:$A$139,0)) -> 65
A22: M21 | B22: Керамогранит у входа Ponza Lilly 200×200 (50 шт) | C22: м² | D22: клей 5 кг × 0,6 + затирка 0,6 кг × 5 + плитка ~60 × 1,08 | E22: 71 | F22: F09 | G22: =INDEX(Ставки!$F$2:$F$139,MATCH(F22,Ставки!$A$2:$A$139,0)) -> 45
A23: M22 | B23: Гидроизоляция санузла обмазочная 2 слоя (пол + стены 300 мм + душевая зона) | C23: м² | D23: Ceresit CR 65 3 кг × 1,84 + лента 0,6 м × 5 | E23: 8.5 | F23: F05 | G23: =INDEX(Ставки!$F$2:$F$139,MATCH(F23,Ставки!$A$2:$A$139,0)) -> 10
A24: M23 | B24: Тёплый пол электрический Nexans (кабель в санузле и прихожей) | C24: м² | D24: лист 13: 2,14 + 0,63 м² (балкон 2,2 м² исключён — незаконно); кабель ~90/м² | E24: 90 | F24: F07 | G24: =INDEX(Ставки!$F$2:$F$139,MATCH(F24,Ставки!$A$2:$A$139,0)) -> 44
A25: M24 | B25: Терморегулятор | C25: шт | D25: программируемый 72 | E25: 72 | F25: ввод | G25: 50 | H25: по прайсам 50–66
A26: M25 | B26: Плинтус МДФ OHZ HM-1540 | C26: м.п. | D26: лист 26: 17 шт × 2,07 м; 7,4 руб./шт + крепёж, герметик | E26: 4.5 | F26: F20 | G26: =INDEX(Ставки!$F$2:$F$139,MATCH(F26,Ставки!$A$2:$A$139,0)) -> 19
A27: M26 | B27: Порожки / стык LVT–керамогранит через герметик | C27: шт | D27: лист 14: латунный/пробковый порожек 20–35 | E27: 28 | F27: F22 | G27: =INDEX(Ставки!$F$2:$F$139,MATCH(F27,Ставки!$A$2:$A$139,0)) -> 25
A28: M27 | B28: Натяжной потолок ПВХ матовый, с материалом и монтажом | C28: м² | D28: лист 17: 45 м²; ставка с материалом | E28: 0 | F28: C03 | G28: =INDEX(Ставки!$F$2:$F$139,MATCH(F28,Ставки!$A$2:$A$139,0)) -> 28 | H28: с материалом
A29: M28 | B29: Теневой профиль EuroLumFer 02 по периметру | C29: м.п. | D29: ставка с материалом 21–39 | E29: 0 | F29: C05 | G29: =INDEX(Ставки!$F$2:$F$139,MATCH(F29,Ставки!$A$2:$A$139,0)) -> 21 | H29: с материалом
A30: M29 | B30: Карнизная ниша LumFer SK Magnum / Levium / Volat | C30: м.п. | D30: лист 17: 9 м.п. SK Magnum + Levium 01 + Volat; профиль ~35/м.п. + монтаж | E30: 35 | F30: ввод | G30: 40 | H30: оценка
A31: M30 | B31: Закладные под светильники и вент. решётку | C31: шт | D31: платформа 5 + монтаж | E31: 5 | F31: ввод | G31: 16 | H31: vache-nebo 16/шт
A32: M31 | B32: Окраска стен MAV Flagman 35, 2 слоя + грунт (УСЛ-1) | C32: м² | D32: лист 12: 50 м²; краска 11 л = 200 руб. ≈ 0,3 л/м² → 5,5 + грунт 0,4 | E32: 6 | F32: X01 | G32: =INDEX(Ставки!$F$2:$F$139,MATCH(F32,Ставки!$A$2:$A$139,0)) -> 10
A33: M32 | B33: Декоративная штукатурка Marmorino Naturale Fine (ДК-1), 2–3 слоя с железнением | C33: м² | D33: лист 12: 61 м²; материал premiumdecor ~18/м² + грунт с кварцем 3 (оценка) | E33: 21 | F33: ввод | G33: 70 | H33: оценка; рынок 35–100
A34: M33 | B34: Обои Grandeco Keen KE1006 (ОБ-1) | C34: м² | D34: лист 12: 23,5 м², 3–4 рулона × ~150 руб. (оценка) | E34: 21 | F34: X08 | G34: =INDEX(Ставки!$F$2:$F$139,MATCH(F34,Ставки!$A$2:$A$139,0)) -> 10
A35: M34 | B35: Фотообои Vinni.by (ФО-1, ФО-2) | C35: м² | D35: лист 12: 12,8 + 4,65 м²; печать ~45/м² (оценка) | E35: 45 | F35: ввод | G35: 15 | H35: оценка
A36: M35 | B36: Плитка Tribeca Sage Green 6×24,6 на стены (PL-1) | C36: м² | D36: лист 12: 6 м²; клей 4 кг + затирка эпокси 0,5 кг × 70 + плитка ~90 × 1,1 | E36: 140 | F36: F13 | G36: =INDEX(Ставки!$F$2:$F$139,MATCH(F36,Ставки!$A$2:$A$139,0)) -> 80 | H36: мелкий формат
A37: M36 | B37: Молдинги на стенах | C37: м.п. | D37: лист 27: 15 м.п.; полиуретан ~12/м.п. (оценка) | E37: 12 | F37: ввод | G37: 15 | H37: оценка
A38: M37 | B38: Микроцемент стены санузла (МКЦ-1) — фикс студии до 20 м², €1 120 | C38: объект | D38: CLAUDE.md: фикс до 20 м²; материал 18 м² × €35 = €630, работа €490 | E38: =630*Параметры!$B$3 -> 2172.681 | F38: ввод | G38: =490*Параметры!$B$3 -> 1689.863 | H38: по курсу из Параметров
A39: M38 | B39: Расходники микроцемент на объект | C39: объект | D39: CLAUDE.md: от €80 | E39: =80*Параметры!$B$3 -> 275.896 | F39: ввод | G39: 0
A40: M39 | B40: Электроточка полная: розетка/выключатель/вывод (штроба + кабель + подрозетник + механизм) | C40: точка | D40: лист 9: 47+2+2 розетки, 4 RJ45, 18 выключателей, 28 выводов = 101; кабель 6 м × 4 + гофра + подрозетник + механизм Vertus ~12 | E40: 42 | F40: E18 | G40: =INDEX(Ставки!$F$2:$F$139,MATCH(F40,Ставки!$A$2:$A$139,0)) -> 90
...

Sheet Объёмы
A1: Ведомость объёмов — Миля 9 (по листам проекта; площади — экспликация листа 5)
A2: Показатель | B2: Значение | C2: Ед. | D2: Основание
A3: Прихожая | B3: 5.69 | C3: м² | D3: лист 5
A4: Санузел | B4: 4.78 | C4: м² | D4: лист 5
A5: Спальня | B5: 10.5 | C5: м² | D5: лист 5
A6: Детская | B6: 13.76 | C6: м² | D6: лист 5
A7: Кухня-гостиная | B7: 19.15 | C7: м² | D7: лист 5
A8: Балкон | B8: 3.15 | C8: м² | D8: лист 5
A9: Площадь без балкона | B9: =SUM(B3:B7) -> 53.88 | C9: м² | D9: расчёт
A10: Площадь с балконом | B10: =SUM(B3:B8) -> 57.03 | C10: м² | D10: расчёт
A11: Демонтаж перегородок и проёмы | B11: =(0.28+0.5+0.26+0.05)*Параметры!$B$11+0.8*2.1+0.9*2.1 -> 6.5457 | C11: м² | D11: лист 3; лист 4 «возводимый дверной проём» 800 и 900
A12: Новые перегородки 120 мм | B12: 5.5 | C12: м² | D12: лист 4: S=5,5, V=0,66 м³
A13: Новые перегородки 100 мм | B13: 11.67 | C13: м² | D13: лист 4: S=11,67, V=1,167 м³
A14: Штукатурка новых перегородок (обе стороны, минус проём 900) | B14: =(B12+B13)*2-0.9*2.1 -> 32.45 | C14: м² | D14: по указанию: штукатурим только возведённые стены
A15: Отделка стен всего по проекту | B15: =B16+B17+B18+B19+B20+B21 -> 175.95 | C15: м² | D15: лист 12, легенда; включает откосы и двери-невидимки
A16: ДК-1 Marmorino | B16: 61 | C16: м² | D16: лист 12
A17: УСЛ-1 покраска MAV | B17: 50 | C17: м² | D17: лист 12
A18: ОБ-1 обои Grandeco | B18: 23.5 | C18: м² | D18: лист 12
A19: ФО-1 + ФО-2 фотообои | B19: =4.65+12.8 -> 17.45 | C19: м² | D19: лист 12
A20: PL-1 плитка Tribeca | B20: 6 | C20: м² | D20: лист 12
A21: МКЦ-1 микроцемент | B21: 18 | C21: м² | D21: лист 12
A22: Шпаклёвка Q3 (под покраску и Marmorino) | B22: =B16+B17 -> 111 | C22: м² | D22: расчёт
A23: Шпаклёвка Q2 (под обои и фотообои) | B23: =B18+B19 -> 40.95 | C23: м² | D23: расчёт
A24: Откосы окон и балконной двери | B24: 20 | C24: м.п. | D24: оценка: 3 окна ≈ 1,75+1,74+1,73 м × (2 × 1,4 + ширина) + балконная дверь
A25: Клеевой винил Quick-Step (без запаса) | B25: 49 | C25: м² | D25: лист 14
A26: Самонивелир 10 мм под винил | B26: =B25 -> 49 | C26: м² | D26: лист 14, узел V1
A27: Керамогранит пол санузла | B27: =B4 -> 4.78 | C27: м² | D27: лист 14: Argenta 120×60, 6 шт
A28: Керамогранит у входа Ponza 200×200 | B28: =50*0.04 -> 2 | C28: м² | D28: лист 14: 50 шт
A29: Гидроизоляция санузла | B29: =B4+9*0.3+2*1.4*2 -> 13.08 | C29: м² | D29: пол + 300 мм по периметру + душевая зона до 2 м
A30: Тёплый пол электрический | B30: =2.14+0.63 -> 2.77 | C30: м² | D30: лист 13; балкон 2,2 м² исключён (п. 8 примечаний — незаконно)
A31: Плинтус МДФ | B31: =17*2.07 -> 35.19 | C31: м.п. | D31: лист 26: 17 шт по 2,07 м
A32: Натяжной потолок | B32: 45 | C32: м² | D32: лист 17
A33: Теневой профиль по периметру | B33: 58 | C33: м.п. | D33: оценка по периметрам комнат минус мебельные зоны
A34: Карнизные ниши LumFer | B34: 9 | C34: м.п. | D34: лист 17: SK Magnum 9 м.п.
A35: Электроточки (розетки, выключатели, выводы, RJ45) | B35: =47+2+2+3+1+7+3+2+1+2+3+28 -> 101 | C35: точка | D35: лист 9, спецификация
A36: Точки света | B36: =44+1+1+1+1+6+1 -> 55 | C36: шт | D36: лист 10, спецификация (без трека)
A37: Точки водоснабжения | B37: 9 | C37: точка | D37: лист 8
A38: Точки канализации | B38: 5 | C38: точка | D38: лист 8
A39: Молдинги | B39: 15 | C39: м.п. | D39: лист 27
A40: Двери межкомнатные | B40: 3 | C40: шт | D40: лист 21
